Workbook

Sheet Metrics
A1: Experiment 1: per-volume metrics (one volume per row, one block per data type)
A2: All values are formulas traced to Parameters, Calibration, Glucose and Inputs. Per-surface values use the interface area in m².
A4: 1. Geometry
A5: Volume (mL) | B5: Volume (L) | C5: Surface (cm²) | D5: Surface (m²) | E5: Liquid height (cm) | F5: SIA (cm⁻¹)
A6: =Inputs!A4 -> 18 | B6: =A6/1000 -> 0.018 | C6: =Inputs!B4 -> 49.43 | D6: =C6/10000 -> 0.004943 | E6: =A6/C6 -> 0.36415133 | F6: =C6/A6 -> 2.7461111
A7: =Inputs!A5 -> 36 | B7: =A7/1000 -> 0.036 | C7: =Inputs!B5 -> 49.85 | D7: =C7/10000 -> 0.004985 | E7: =A7/C7 -> 0.7221665 | F7: =C7/A7 -> 1.3847222
A8: =Inputs!A6 -> 54 | B8: =A8/1000 -> 0.054 | C8: =Inputs!B6 -> 50.26 | D8: =C8/10000 -> 0.005026 | E8: =A8/C8 -> 1.0744131 | F8: =C8/A8 -> 0.93074074
A9: =Inputs!A7 -> 72 | B9: =A9/1000 -> 0.072 | C9: =Inputs!B7 -> 50.67 | D9: =C9/10000 -> 0.005067 | E9: =A9/C9 -> 1.4209591 | F9: =C9/A9 -> 0.70375
A10: =Inputs!A8 -> 90 | B10: =A10/1000 -> 0.09 | C10: =Inputs!B8 -> 51.08 | D10: =C10/10000 -> 0.005108 | E10: =A10/C10 -> 1.7619421 | F10: =C10/A10 -> 0.56755556
A11: =Inputs!A9 -> 108 | B11: =A11/1000 -> 0.108 | C11: =Inputs!B9 -> 51.49 | D11: =C11/10000 -> 0.005149 | E11: =A11/C11 -> 2.0974947 | F11: =C11/A11 -> 0.47675926
A12: =Inputs!A10 -> 126 | B12: =A12/1000 -> 0.126 | C12: =Inputs!B10 -> 51.9 | D12: =C12/10000 -> 0.00519 | E12: =A12/C12 -> 2.4277457 | F12: =C12/A12 -> 0.41190476
A15: 2. Substrate supply
A16: Volume (mL) | B16: Initial glucose (g L⁻¹) | C16: Initial glucose per vessel (g) | D16: Glucose load (g m⁻²)
A17: =Inputs!A4 -> 18 | B17: =Parameters!$B$6 -> 18.182369 | C17: =B17*B6 -> 0.32728264 | D17: =C17/D6 -> 66.211336
A18: =Inputs!A5 -> 36 | B18: =Parameters!$B$6 -> 18.182369 | C18: =B18*B7 -> 0.65456527 | D18: =C18/D7 -> 131.30698
A19: =Inputs!A6 -> 54 | B19: =Parameters!$B$6 -> 18.182369 | C19: =B19*B8 -> 0.98184791 | D19: =C19/D8 -> 195.35374
A20: =Inputs!A7 -> 72 | B20: =Parameters!$B$6 -> 18.182369 | C20: =B20*B9 -> 1.3091305 | D20: =C20/D9 -> 258.36403
A21: =Inputs!A8 -> 90 | B21: =Parameters!$B$6 -> 18.182369 | C21: =B21*B10 -> 1.6364132 | D21: =C21/D10 -> 320.3628
A22: =Inputs!A9 -> 108 | B22: =Parameters!$B$6 -> 18.182369 | C22: =B22*B11 -> 1.9636958 | D22: =C22/D11 -> 381.37421
A23: =Inputs!A10 -> 126 | B23: =Parameters!$B$6 -> 18.182369 | C23: =B23*B12 -> 2.2909785 | D23: =C23/D12 -> 441.42167
A26: 3. Glucose, days 0–7
A27: Volume (mL) | B27: Residual at day 7 (g L⁻¹) | C27: Consumed (g L⁻¹) | D27: Consumed (g) | E27: Consumed per surface (g m⁻²) | F27: Consumed (% of initial) | G27: Mean uptake rate (g L⁻¹ d⁻¹) | H27: Uptake rate per vessel (g d⁻¹) | I27: Uptake rate per surface (g m⁻² d⁻¹) | J27: Remaining at day 7 (g) | K27: Remaining per surface (g m⁻²)
A28: =Inputs!A4 -> 18 | B28: =IF(AND(Parameters!$B$15=1,Glucose!I4<Calibration!$B$16),0,Glucose!I4) -> 3.0762037 | C28: =B17-B28 -> 15.106165 | D28: =C28*B6 -> 0.27191097 | E28: =D28/D6 -> 55.0093 | F28: =D28/C17 -> 0.83081392 | G28: =C28/Parameters!$B$7 -> 2.1580236 | H28: =D28/Parameters!$B$7 -> 0.038844424 | I28: =E28/Parameters!$B$7 -> 7.8584714 | J28: =B28*B6 -> 0.055371667 | K28: =J28/D6 -> 11.202037
A29: =Inputs!A5 -> 36 | B29: =IF(AND(Parameters!$B$15=1,Glucose!I5<Calibration!$B$16),0,Glucose!I5) -> 3.3630481 | C29: =B18-B29 -> 14.819321 | D29: =C29*B7 -> 0.53349554 | E29: =D29/D7 -> 107.02017 | F29: =D29/C18 -> 0.81503795 | G29: =C29/Parameters!$B$7 -> 2.1170458 | H29: =D29/Parameters!$B$7 -> 0.076213648 | I29: =E29/Parameters!$B$7 -> 15.288595 | J29: =B29*B7 -> 0.12106973 | K29: =J29/D7 -> 24.286807
A30: =Inputs!A6 -> 54 | B30: =IF(AND(Parameters!$B$15=1,Glucose!I6<Calibration!$B$16),0,Glucose!I6) -> 5.5719955 | C30: =B19-B30 -> 12.610373 | D30: =C30*B8 -> 0.68096015 | E30: =D30/D8 -> 135.4875 | F30: =D30/C19 -> 0.69354953 | G30: =C30/Parameters!$B$7 -> 1.8014819 | H30: =D30/Parameters!$B$7 -> 0.097280022 | I30: =E30/Parameters!$B$7 -> 19.355357 | J30: =B30*B8 -> 0.30088775 | K30: =J30/D8 -> 59.866246
A31: =Inputs!A7 -> 72 | B31: =IF(AND(Parameters!$B$15=1,Glucose!I7<Calibration!$B$16),0,Glucose!I7) -> 7.0062176 | C31: =B20-B31 -> 11.176151 | D31: =C31*B9 -> 0.80468288 | E31: =D31/D9 -> 158.80854 | F31: =D31/C20 -> 0.6146697 | G31: =C31/Parameters!$B$7 -> 1.596593 | H31: =D31/Parameters!$B$7 -> 0.1149547 | I31: =E31/Parameters!$B$7 -> 22.686934 | J31: =B31*B9 -> 0.50444767 | K31: =J31/D9 -> 99.55549
A32: =Inputs!A8 -> 90 | B32: =IF(AND(Parameters!$B$15=1,Glucose!I8<Calibration!$B$16),0,Glucose!I8) -> 9.4358145 | C32: =B21-B32 -> 8.7465542 | D32: =C32*B10 -> 0.78718988 | E32: =D32/D10 -> 154.10922 | F32: =D32/C21 -> 0.48104592 | G32: =C32/Parameters!$B$7 -> 1.2495077 | H32: =D32/Parameters!$B$7 -> 0.1124557 | I32: =E32/Parameters!$B$7 -> 22.015602 | J32: =B32*B10 -> 0.8492233 | K32: =J32/D10 -> 166.25358
A33: =Inputs!A9 -> 108 | B33: =IF(AND(Parameters!$B$15=1,Glucose!I9<Calibration!$B$16),0,Glucose!I9) -> 8.1070138 | C33: =B22-B33 -> 10.075355 | D33: =C33*B11 -> 1.0881383 | E33: =D33/D11 -> 211.33003 | F33: =D33/C22 -> 0.55412774 | G33: =C33/Parameters!$B$7 -> 1.4393364 | H33: =D33/Parameters!$B$7 -> 0.15544833 | I33: =E33/Parameters!$B$7 -> 30.190004 | J33: =B33*B11 -> 0.87555749 | K33: =J33/D11 -> 170.04418
A34: =Inputs!A10 -> 126 | B34: =IF(AND(Parameters!$B$15=1,Glucose!I10<Calibration!$B$16),0,Glucose!I10) -> 11.416757 | C34: =B23-B34 -> 6.7656114 | D34: =C34*B12 -> 0.85246704 | E34: =D34/D12 -> 164.25184 | F34: =D34/C23 -> 0.37209736 | G34: =C34/Parameters!$B$7 -> 0.96651592 | H34: =D34/Parameters!$B$7 -> 0.12178101 | I34: =E34/Parameters!$B$7 -> 23.464548 | J34: =B34*B12 -> 1.4385114 | K34: =J34/D12 -> 277.16983
A37: 4. Glucose, days 7–14 (measured)
A38: Volume (mL) | B38: Residual at day 14 (g L⁻¹) | C38: Consumed (g L⁻¹) | D38: Consumed (g) | E38: Consumed per surface (g m⁻²) | F38: Consumed (% of initial) | G38: Mean uptake rate (g L⁻¹ d⁻¹) | H38: Uptake rate per vessel (g d⁻¹) | I38: Uptake rate per surface (g m⁻² d⁻¹) | J38: Remaining at day 14 (g) | K38: Remaining per surface (g m⁻²) | L38: Below detection limit at day 14
A39: =Inputs!A4 -> 18 | B39: =IF(AND(Parameters!$B$15=1,Glucose!R4<Calibration!$B$16),0,Glucose!R4) -> 0.63557437 | C39: =B28-B39 -> 2.4406293 | D39: =C39*B6 -> 0.043931328 | E39: =D39/D6 -> 8.8875841 | F39: =D39/C17 -> 0.13423055 | G39: =C39/(Parameters!$B$8-Parameters!$B$7) -> 0.34866133 | H39: =D39/(Parameters!$B$8-Parameters!$B$7) -> 0.006275904 | I39: =E39/(Parameters!$B$8-Parameters!$B$7) -> 1.2696549 | J39: =B39*B6 -> 0.011440339 | K39: =J39/D6 -> 2.3144525 | L39: =Glucose!S4 -> yes
A40: =Inputs!A5 -> 36 | B40: =IF(AND(Parameters!$B$15=1,Glucose!R5<Calibration!$B$16),0,Glucose!R5) -> 0.64660685 | C40: =B29-B40 -> 2.7164413 | D40: =C40*B7 -> 0.097791887 | E40: =D40/D7 -> 19.617229 | F40: =D40/C18 -> 0.14939975 | G40: =C40/(Parameters!$B$8-Parameters!$B$7) -> 0.38806304 | H40: =D40/(Parameters!$B$8-Parameters!$B$7) -> 0.01397027 | I40: =E40/(Parameters!$B$8-Parameters!$B$7) -> 2.8024613 | J40: =B40*B7 -> 0.023277847 | K40: =J40/D7 -> 4.6695781 | L40: =Glucose!S5 -> yes
A41: =Inputs!A6 -> 54 | B41: =IF(AND(Parameters!$B$15=1,Glucose!R6<Calibration!$B$16),0,Glucose!R6) -> 0.66499431 | C41: =B30-B41 -> 4.9070011 | D41: =C41*B8 -> 0.26497806 | E41: =D41/D8 -> 52.721461 | F41: =D41/C19 -> 0.26987689 | G41: =C41/(Parameters!$B$8-Parameters!$B$7) -> 0.70100016 | H41: =D41/(Parameters!$B$8-Parameters!$B$7) -> 0.037854009 | I41: =E41/(Parameters!$B$8-Parameters!$B$7) -> 7.5316372 | J41: =B41*B8 -> 0.035909693 | K41: =J41/D8 -> 7.1447857 | L41: =Glucose!S6 -> yes
A42: =Inputs!A7 -> 72 | B42: =IF(AND(Parameters!$B$15=1,Glucose!R7<Calibration!$B$16),0,Glucose!R7) -> 0.63189688 | C42: =B31-B42 -> 6.3743207 | D42: =C42*B9 -> 0.45895109 | E42: =D42/D9 -> 90.576494 | F42: =D42/C20 -> 0.35057703 | G42: =C42/(Parameters!$B$8-Parameters!$B$7) -> 0.91061725 | H42: =D42/(Parameters!$B$8-Parameters!$B$7) -> 0.065564442 | I42: =E42/(Parameters!$B$8-Parameters!$B$7) -> 12.939499 | J42: =B42*B9 -> 0.045496575 | K42: =J42/D9 -> 8.9789965 | L42: =Glucose!S7 -> yes
A43: =Inputs!A8 -> 90 | B43: =IF(AND(Parameters!$B$15=1,Glucose!R8<Calibration!$B$16),0,Glucose!R8) -> 1.1614558 | C43: =B32-B43 -> 8.2743587 | D43: =C43*B10 -> 0.74469228 | E43: =D43/D10 -> 145.7894 | F43: =D43/C21 -> 0.45507595 | G43: =C43/(Parameters!$B$8-Parameters!$B$7) -> 1.1820512 | H43: =D43/(Parameters!$B$8-Parameters!$B$7) -> 0.10638461 | I43: =E43/(Parameters!$B$8-Parameters!$B$7) -> 20.827058 | J43: =B43*B10 -> 0.10453102 | K43: =J43/D10 -> 20.464179 | L43: =Glucose!S8 -> no
A44: =Inputs!A9 -> 108 | B44: =IF(AND(Parameters!$B$15=1,Glucose!R9<Calibration!$B$16),0,Glucose!R9) -> 2.1764438 | C44: =B33-B44 -> 5.9305699 | D44: =C44*B11 -> 0.64050155 | E44: =D44/D11 -> 124.39339 | F44: =D44/C22 -> 0.32617147 | G44: =C44/(Parameters!$B$8-Parameters!$B$7) -> 0.84722428 | H44: =D44/(Parameters!$B$8-Parameters!$B$7) -> 0.091500222 | I44: =E44/(Parameters!$B$8-Parameters!$B$7) -> 17.770484 | J44: =B44*B11 -> 0.23505593 | K44: =J44/D11 -> 45.650793 | L44: =Glucose!S9 -> no
A45: =Inputs!A10 -> 126 | B45: =IF(AND(Parameters!$B$15=1,Glucose!R10<Calibration!$B$16),0,Glucose!R10) -> 4.3130671 | C45: =B34-B45 -> 7.1036901 | D45: =C45*B12 -> 0.89506496 | E45: =D45/D12 -> 172.45953 | F45: =D45/C23 -> 0.39069113 | G45: =C45/(Parameters!$B$8-Parameters!$B$7) -> 1.0148129 | H45: =D45/(Parameters!$B$8-Parameters!$B$7) -> 0.12786642 | I45: =E45/(Parameters!$B$8-Parameters!$B$7) -> 24.637076 | J45: =B45*B12 -> 0.54344646 | K45: =J45/D12 -> 104.7103 | L45: =Glucose!S10 -> no
A48: 5. Glucose, days 7–14 (Equation 4, active-consumption window)
A49: Volume (mL) | B49: Uptake rate (g L⁻¹ d⁻¹) | C49: Uptake rate per vessel (g d⁻¹) | D49: Uptake rate per surface (g m⁻² d⁻¹)
...

Sheet README
A1: Experiment 1: per-volume metrics (LSSF, Trametes versicolor)
A3: How to read this workbook
A4: Blue text = typed inputs (raw data or parameters). Black = formulas. Green = formulas linking to another sheet. Yellow fill = parameter you may want to change.
A5: Sheets: Parameters -> Calibration (DNS curve) -> Glucose (OD to g/L) and Inputs (biomass, surfaces) -> Metrics (one volume per row, one block per data type).
A7: Sources
A8: Glucose OD540: data/raw/Exp1_glucose.xlsx (Plate 1: standards cols 1-3, day 14 cols 4-6; Plate 2: day 7 cols 10-12). Sample dilution 20x.
A9: Fresh biomass (FBM): data/raw/Exp1_biomass_pH.xlsx, one culture per volume and day.
A10: Surface areas: vessel geometry, as in Exp1.Rmd (my_surfaces).
A11: Equation 4 coefficients: R output of lm(glu ~ Time + Volume) after the calibration fix (8 Oct 2026).
A13: Assumptions and decisions
A14: 1. Medium: 2% glucose monohydrate; initial glucose expressed as anhydrous equivalent (20 x 180.16/198.17 = 18.18 g/L).
A15: 2. Standards prepared from glucose dried at 60 C, treated as anhydrous. DNS reaction at 95 C.
... A21: 8. "Per surface" values use the air-liquid interface area in m2.

Sheet Parameters
A1: Parameters
A2: Parameter | B2: Value | C2: Unit | D2: Note / source
A3: Glucose monohydrate in medium | B3: 20 | C3: g/L | D3: 2% (w/v) D-glucose monohydrate in CYM
A4: Molar mass, anhydrous glucose | B4: 180.16 | C4: g/mol
A5: Molar mass, glucose monohydrate | B5: 198.17 | C5: g/mol
A6: Initial glucose, s0 (anhydrous) | B6: =B3*B4/B5 -> 18.182369 | C6: g/L | D6: Calculated
A7: First sampling day | B7: 7 | C7: d
A8: Final sampling day | B8: 14 | C8: d
A9: Fresh-to-dry biomass factor | B9: 0.0547 | C9: g/g | D9: Fresh vs lyophilised fit (R2 = 0.970, n = 22)
A10: Inoculum biomass concentration | B10: =5/18 -> 0.27777778 | C10: g/mL | D10: 5 g in 18 mL (Exp1.Rmd: inoc_bio)
A11: Inoculum fraction of culture volume | B11: =1/6 -> 0.16666667 | C11: - | D11: Inoculum : CYM = 1 : 5
A12: Unit factor for inoculum term | B12: 1000 | C12: - | D12: As in Exp1.Rmd (inoc_bio x V/6/1000)
A13: Standards, in-well dilution | B13: 10 | C13: x
A14: Samples, dilution | B14: 20 | C14: x | D14: From Exp1_glucose.xlsx dilution block
A15: Treat values below detection limit as 0 (1 = yes, 0 = no) | B15: 0 | C15: - | D15: Default 0 = use measured values
A16: Equation 4, intercept | B16: 8.034804 | C16: g/L | D16: R: lm(glu ~ Time + Volume)
A17: Equation 4, beta1 (Time) | B17: -0.987713 | C17: g L-1 d-1 | D17: R: lm(glu ~ Time + Volume)
A18: Equation 4, beta2 (Volume) | B18: 0.0748 | C18: g L-1 mL-1 | D18: R: lm(glu ~ Time + Volume)

Sheet Calibration
A1: DNS calibration curve (anhydrous glucose standards)
A3: Standard (g/L) | B3: In-well (g/L) | C3: OD rep 1 | D3: OD rep 2 | E3: OD rep 3 | F3: Mean OD | G3: Used in fit
A4: 2 | B4: =A4/Parameters!$B$13 -> 0.2 | C4: 0.565 | D4: 0.566 | E4: 0.563 | F4: =AVERAGE(C4:E4) -> 0.56466667 | G4: =IF(A4>=0.4,"yes","no") -> yes
A5: 1 | B5: =A5/Parameters!$B$13 -> 0.1 | C5: 0.282 | D5: 0.286 | E5: 0.28 | F5: =AVERAGE(C5:E5) -> 0.28266667 | G5: =IF(A5>=0.4,"yes","no") -> yes
A6: 0.8 | B6: =A6/Parameters!$B$13 -> 0.08 | C6: 0.233 | D6: 0.23 | E6: 0.226 | F6: =AVERAGE(C6:E6) -> 0.22966667 | G6: =IF(A6>=0.4,"yes","no") -> yes
A7: 0.6 | B7: =A7/Parameters!$B$13 -> 0.06 | C7: 0.181 | D7: 0.18 | E7: 0.177 | F7: =AVERAGE(C7:E7) -> 0.17933333 | G7: =IF(A7>=0.4,"yes","no") -> yes
A8: 0.4 | B8: =A8/Parameters!$B$13 -> 0.04 | C8: 0.138 | D8: 0.135 | E8: 0.13 | F8: =AVERAGE(C8:E8) -> 0.13433333 | G8: =IF(A8>=0.4,"yes","no") -> yes
A9: 0.2 | B9: =A9/Parameters!$B$13 -> 0.02 | C9: 0.102 | D9: 0.105 | E9: 0.102 | F9: =AVERAGE(C9:E9) -> 0.103 | G9: =IF(A9>=0.4,"yes","no") -> no
A10: 0 | B10: =A10/Parameters!$B$13 -> 0 | C10: 0.098 | D10: 0.097 | E10: 0.105 | F10: =AVERAGE(C10:E10) -> 0.1 | G10: =IF(A10>=0.4,"yes","no") -> no
A12: Fit: mean OD = a + b x in-well concentration (standards 0.4-2 g/L, rows 4-8)
A13: Slope, b (OD per g/L in well) | B13: =SLOPE(F4:F8,B4:B8) -> 2.719244
A14: Intercept, a (OD) | B14: =INTERCEPT(F4:F8,B4:B8) -> 0.017085911
A15: R2 | B15: =RSQ(F4:F8,B4:B8) -> 0.998682
A16: Detection limit in sample (g/L) | B16: =MIN(B4:B8)*Parameters!$B$14 -> 0.8 | C16: Lowest calibrated standard (in well) x sample dilution

Sheet Glucose
A1: Residual reducing sugars: OD540 to g/L (conc = max((OD - a)/b, 0) x dilution)
B2: Day 7 (Plate 2, columns 10-12) | K2: Day 14 (Plate 1, columns 4-6)
A3: Volume (mL) | B3: OD rep 1 | C3: OD rep 2 | D3: OD rep 3 | E3: Dilution | F3: Conc rep 1 (g/L) | G3: Conc rep 2 (g/L) | H3: Conc rep 3 (g/L) | I3: Mean (g/L) | J3: Below detection limit | K3: OD rep 1 | L3: OD rep 2 | M3: OD rep 3 | N3: Dilution | O3: Conc rep 1 (g/L) | P3: Conc rep 2 (g/L) | Q3: Conc rep 3 (g/L) | R3: Mean (g/L) | S3: Below detection limit
A4: 18 | B4: 0.395 | C4: 0.454 | D4: 0.457 | E4: =Parameters!$B$14 -> 20 | F4: =IF(B4="","",MAX((B4-Calibration!$B$14)/Calibration!$B$13,0)*$E4) -> 2.7795526 | G4: =IF(C4="","",MAX((C4-Calibration!$B$14)/Calibration!$B$13,0)*$E4) -> 3.2134968 | H4: =IF(D4="","",MAX((D4-Calibration!$B$14)/Calibration!$B$13,0)*$E4) -> 3.2355617 | I4: =AVERAGE(F4:H4) -> 3.0762037 | J4: =IF(I4<Calibration!$B$16,"yes","no") -> no | L4: 0.102 | M4: 0.105 | N4: =Parameters!$B$14 -> 20 | O4: =IF(K4="","",MAX((K4-Calibration!$B$14)/Calibration!$B$13,0)*$N4) | P4: =IF(L4="","",MAX((L4-Calibration!$B$14)/Calibration!$B$13,0)*$N4) -> 0.62454189 | Q4: =IF(M4="","",MAX((M4-Calibration!$B$14)/Calibration!$B$13,0)*$N4) -> 0.64660685 | R4: =AVERAGE(O4:Q4) -> 0.63557437 | S4: =IF(R4<Calibration!$B$16,"yes","no") -> yes
A5: 36 | B5: 0.434 | C5: 0.49 | D5: 0.499 | E5: =Parameters!$B$14 -> 20 | F5: =IF(B5="","",MAX((B5-Calibration!$B$14)/Calibration!$B$13,0)*$E5) -> 3.0663971 | G5: =IF(C5="","",MAX((C5-Calibration!$B$14)/Calibration!$B$13,0)*$E5) -> 3.4782763 | H5: =IF(D5="","",MAX((D5-Calibration!$B$14)/Calibration!$B$13,0)*$E5) -> 3.5444711 | I5: =AVERAGE(F5:H5) -> 3.3630481 | J5: =IF(I5<Calibration!$B$16,"yes","no") -> no | L5: 0.107 | M5: 0.103 | N5: =Parameters!$B$14 -> 20 | O5: =IF(K5="","",MAX((K5-Calibration!$B$14)/Calibration!$B$13,0)*$N5) | P5: =IF(L5="","",MAX((L5-Calibration!$B$14)/Calibration!$B$13,0)*$N5) -> 0.66131682 | Q5: =IF(M5="","",MAX((M5-Calibration!$B$14)/Calibration!$B$13,0)*$N5) -> 0.63189688 | R5: =AVERAGE(O5:Q5) -> 0.64660685 | S5: =IF(R5<Calibration!$B$16,"yes","no") -> yes
A6: 54 | B6: 0.724 | C6: 0.79 | D6: 0.81 | E6: =Parameters!$B$14 -> 20 | F6: =IF(B6="","",MAX((B6-Calibration!$B$14)/Calibration!$B$13,0)*$E6) -> 5.1993429 | G6: =IF(C6="","",MAX((C6-Calibration!$B$14)/Calibration!$B$13,0)*$E6) -> 5.6847719 | H6: =IF(D6="","",MAX((D6-Calibration!$B$14)/Calibration!$B$13,0)*$E6) -> 5.8318716 | I6: =AVERAGE(F6:H6) -> 5.5719955 | J6: =IF(I6<Calibration!$B$16,"yes","no") -> no | L6: 0.104 | M6: 0.111 | N6: =Parameters!$B$14 -> 20 | O6: =IF(K6="","",MAX((K6-Calibration!$B$14)/Calibration!$B$13,0)*$N6) | P6: =IF(L6="","",MAX((L6-Calibration!$B$14)/Calibration!$B$13,0)*$N6) -> 0.63925186 | Q6: =IF(M6="","",MAX((M6-Calibration!$B$14)/Calibration!$B$13,0)*$N6) -> 0.69073676 | R6: =AVERAGE(O6:Q6) -> 0.66499431 | S6: =IF(R6<Calibration!$B$16,"yes","no") -> yes
A7: 72 | B7: 0.98 | C7: 0.897 | D7: 1.032 | E7: =Parameters!$B$14 -> 20 | F7: =IF(B7="","",MAX((B7-Calibration!$B$14)/Calibration!$B$13,0)*$E7) -> 7.0822191 | G7: =IF(C7="","",MAX((C7-Calibration!$B$14)/Calibration!$B$13,0)*$E7) -> 6.4717553 | H7: =IF(D7="","",MAX((D7-Calibration!$B$14)/Calibration!$B$13,0)*$E7) -> 7.4646784 | I7: =AVERAGE(F7:H7) -> 7.0062176 | J7: =IF(I7<Calibration!$B$16,"yes","no") -> no | L7: 0.103 | M7: 0.103 | N7: =Parameters!$B$14 -> 20 | O7: =IF(K7="","",MAX((K7-Calibration!$B$14)/Calibration!$B$13,0)*$N7) | P7: =IF(L7="","",MAX((L7-Calibration!$B$14)/Calibration!$B$13,0)*$N7) -> 0.63189688 | Q7: =IF(M7="","",MAX((M7-Calibration!$B$14)/Calibration!$B$13,0)*$N7) -> 0.63189688 | R7: =AVERAGE(O7:Q7) -> 0.63189688 | S7: =IF(R7<Calibration!$B$16,"yes","no") -> yes
A8: 90 | B8: 1.272 | C8: 1.327 | D8: 1.301 | E8: =Parameters!$B$14 -> 20 | F8: =IF(B8="","",MAX((B8-Calibration!$B$14)/Calibration!$B$13,0)*$E8) -> 9.2298749 | G8: =IF(C8="","",MAX((C8-Calibration!$B$14)/Calibration!$B$13,0)*$E8) -> 9.6343991 | H8: =IF(D8="","",MAX((D8-Calibration!$B$14)/Calibration!$B$13,0)*$E8) -> 9.4431695 | I8: =AVERAGE(F8:H8) -> 9.4358145 | J8: =IF(I8<Calibration!$B$16,"yes","no") -> no | L8: 0.176 | M8: 0.174 | N8: =Parameters!$B$14 -> 20 | O8: =IF(K8="","",MAX((K8-Calibration!$B$14)/Calibration!$B$13,0)*$N8) | P8: =IF(L8="","",MAX((L8-Calibration!$B$14)/Calibration!$B$13,0)*$N8) -> 1.1688108 | Q8: =IF(M8="","",MAX((M8-Calibration!$B$14)/Calibration!$B$13,0)*$N8) -> 1.1541008 | R8: =AVERAGE(O8:Q8) -> 1.1614558 | S8: =IF(R8<Calibration!$B$16,"yes","no") -> no
A9: 108 | B9: 1.07 | C9: 1.139 | D9: 1.149 | E9: =Parameters!$B$14 -> 20 | F9: =IF(B9="","",MAX((B9-Calibration!$B$14)/Calibration!$B$13,0)*$E9) -> 7.7441678 | G9: =IF(C9="","",MAX((C9-Calibration!$B$14)/Calibration!$B$13,0)*$E9) -> 8.2516618 | H9: =IF(D9="","",MAX((D9-Calibration!$B$14)/Calibration!$B$13,0)*$E9) -> 8.3252117 | I9: =AVERAGE(F9:H9) -> 8.1070138 | J9: =IF(I9<Calibration!$B$16,"yes","no") -> no | L9: 0.312 | M9: 0.314 | N9: =Parameters!$B$14 -> 20 | O9: =IF(K9="","",MAX((K9-Calibration!$B$14)/Calibration!$B$13,0)*$N9) | P9: =IF(L9="","",MAX((L9-Calibration!$B$14)/Calibration!$B$13,0)*$N9) -> 2.1690888 | Q9: =IF(M9="","",MAX((M9-Calibration!$B$14)/Calibration!$B$13,0)*$N9) -> 2.1837988 | R9: =AVERAGE(O9:Q9) -> 2.1764438 | S9: =IF(R9<Calibration!$B$16,"yes","no") -> no
A10: 126 | B10: 1.562 | C10: 1.586 | D10: 1.56 | E10: =Parameters!$B$14 -> 20 | F10: =IF(B10="","",MAX((B10-Calibration!$B$14)/Calibration!$B$13,0)*$E10) -> 11.362821 | G10: =IF(C10="","",MAX((C10-Calibration!$B$14)/Calibration!$B$13,0)*$E10) -> 11.53934 | H10: =IF(D10="","",MAX((D10-Calibration!$B$14)/Calibration!$B$13,0)*$E10) -> 11.348111 | I10: =AVERAGE(F10:H10) -> 11.416757 | J10: =IF(I10<Calibration!$B$16,"yes","no") -> no | L10: 0.598 | M10: 0.609 | N10: =Parameters!$B$14 -> 20 | O10: =IF(K10="","",MAX((K10-Calibration!$B$14)/Calibration!$B$13,0)*$N10) | P10: =IF(L10="","",MAX((L10-Calibration!$B$14)/Calibration!$B$13,0)*$N10) -> 4.2726147 | Q10: =IF(M10="","",MAX((M10-Calibration!$B$14)/Calibration!$B$13,0)*$N10) -> 4.3535195 | R10: =AVERAGE(O10:Q10) -> 4.3130671 | S10: =IF(R10<Calibration!$B$16,"yes","no") -> no
A12: Day 14, replicate 1 (column K) is left empty on purpose: excluded as a likely well-loading error (raw OD in the cell comment).

Sheet Inputs
A1: Geometry and biomass inputs
A3: Volume (mL) | B3: Surface (cm2) | C3: Fresh biomass day 7 (g) | D3: Fresh biomass day 14 (g)
A4: 18 | B4: 49.43 | C4: 3.3 | D4: 1.8
A5: 36 | B5: 49.85 | C5: 4.3 | D5: 2.7
A6: 54 | B6: 50.26 | C6: 4.7 | D6: 4.7
A7: 72 | B7: 50.67 | C7: 4.8 | D7: 6.7
A8: 90 | B8: 51.08 | C8: 4.1 | D8: 8.1
A9: 108 | B9: 51.49 | C9: 3.6 | D9: 8.3
A10: 126 | B10: 51.9 | C10: 1.80875 | D10: 7.4
A12: Surface: vessel geometry (Exp1.Rmd, my_surfaces). Fresh biomass: Exp1_biomass_pH.xlsx (column FBM).
